Workbook

Sheet INSTRUCTIONS
B2: INSTRUCTIONS
B4: This is a spreadsheet developed to track the metrics of each dental provider and differs slightly from the official IRT Exercise Metrics Tracker. This is a tool meant to make metrics tracking easier for the Dental Department OIC at each site. You will be required to report metrics to you site OIC as well as the Exercise Dental OIC.
B6: 1. Verify the exercise details - Left click on the "ProjectDetails" worksheet tab at the bottom of the screen. Verify the Exercise Name, Site Locations, Service Delivery Dates, and Participating Service information in the cells in Column "B" exactly match the infromation listed in the corresponding cells on the IRT Exercise Metrics Tracker. If it does not macth exactly, please make the necessary chnges on this spreadsheet.
B8: NOTE: This spreadsheet has individual provider information added whereas the IRT Exercise Metrics Tracker does not!
B10: 2. Enter Provider information - In cells B45 to B54 enter your providers' service and in C45 to C54 their rank and name. Service must be selected from the drop down menu. Any text may be entered for rank and name. Use rank conventions listed by service to the right.
B12: 3. Verify information on the "Day1" worksheet - Open the "Day1" worksheet and verify that the exercise name, date, providers and their service has properly autofilled. The "Site Location" must be entered in cell B4 on the "Day1" worksheet only. Select your site from the drop down list. This choice will autofill to the "Day2" through "Day10" worksheets.
B14: 4. Verify provider information - Verify that your providers' names and services are correct in cells C92 to L92, and C93 to L93.
B16: 5. IMPORTANT: Verify accuracy of formulas for service totals - Verify that the service total formulas in cells M94 to S94 contain the correct service acronym displaying in cells M5 to S5. The acronym (or a blank space if there is none) is placed between the quotation marks (" ") in the formula. Unlock the worksheet using the password "IRT2020" and correct the formula if necessary, and copy and paste the FORMULA ONLY in the column's cells in rows 95 to 162. You will have to repeat this procedure on "Day2" to "Day10" worksheets.
B18: 6. Collect clinical data - Collect daily patient data from your providers by having them use individual tally or "DIRS" sheets. You can print off the last worksheet in theis work book, or a .pdf file is available. You should have each provder sill one out each day. No personal informaiton is gathered on patents, only how many of each procudure was done. Metrics should be collected daily by the time set by your site OIC.
B20: 7. Enter provider data in the daily worksheet - Transfer the DIRS totals for each provider in columns "C" through "L" of the corresponding day worksheet. Data in the other cells will autofill due to formulas. Each provider's total procedures and dollar value for the exercise will display in the "Provider Summary" worksheet.
B22: NOTE: "Patient Seating" appears on the dental metrics tracker and NOT on the exercise tracker.
B24: 8. Transfer the data to the site metrics tracker - Select cells M94 through S162 by left clicking and holding the mouse button, then drag the cursor to the right to cell S94, and then down to S162. Right click and select "Copy". IMPORTANT: Do not copy the "Patient Seating" data! This is not reported on the site or exercise tracker. Open up the corresponding day worksheet on the IRT Exercise Metrics Tracker. Right click on the appropriate cell and paste the VALUES ONLY by selecting the paste icon (second one) with numbers.
... B32: For IRT Puerto Rico, we forgot to code for local anesthesia given (D9215) so I went back into this spreadsheet and added these codes with a best guess as to how many patients received local based on what procedures the provider did that day and also based on how many patients the provider saw. Even though we don't normally bill for this code in private practice, for the MHS UBO rates there is a value attached to that AND it states it's in conjunction with an operative or surgical procedure

Sheet 2024 Rates
A1: Description Name | B1: Code | C1: DOD Weight | D1: Full Rate
A2: Periodic oral evaluation – established patient | B2: D0120 | C2: 0.62 | D2: 71.74
A3: Limited oral evaluation – problem focused | B3: D0140 | C3: 0.93 | D3: 107.61
A4: Oral evaluation for a patient under three years of age and counseling with primary caregiver | B4: D0145 | C4: 0.91 | D4: 105.3
A5: Comprehensive oral evaluation – new or established patient | B5: D0150 | C5: 1.05 | D5: 121.5
A6: Detailed and extensive oral evaluation – problem focused, by report | B6: D0160 | C6: 1.58 | D6: 182.82
A7: Re‐evaluation – post-operative office visit | B7: D0171 | C7: 0.75 | D7: 86.78
A8: Screening of a patient | B8: D0190 | C8: 0.5 | D8: 57.86
A9: Intraoral - comprehensive series of radiographic images | B9: D0210 | C9: 1.64 | D9: 189.77
A10: Intraoral – periapical first radiographic image | B10: D0220 | C10: 0.36 | D10: 41.66
A11: Intraoral – periapical each additional radiographic image | B11: D0230 | C11: 0.3 | D11: 34.71
A12: Intraoral – occlusal radiographic image | B12: D0240 | C12: 0.44 | D12: 50.91
A13: Bitewing – single radiographic image | B13: D0270 | C13: 0.37 | D13: 42.81
... A84: Patient treated | B84: W9999 | C84: 0 | D84: 0

Sheet SourceValues
F1: To update this spreadsheet: Update the RVU conversion factor from CMS, google search
A2: Operational Workload, Utilizing Relative Value Units (RVUs) | F2: Update each medical / nutrition counseling / eye procedure RVU and non-facility RVU via CMS website
A3: Mission Name: ECG IRT | G3: using "National Fee Schedule" keyword to search. 2020 file is located at https://www.cms.gov/Medicare/Medicare-Fee-for-Service-Payment/PhysicianFeeSched/PFS-Relative-Value-Files.html
A4: Procedure | B4: CPT | C4: Worked RVU | D4: Non-Facility RVU | E4: Global Value
A5: Dental | D5: CY2024 RVU Conversion Factor Dental: | E5: 115.71 | F5: Updated worked RVU and global values for CY 2022 from:
A6: Periodic oral evaluation – established patient | B6: D0120 | C6: 0.62 | D6: =(C6*$E$5)/100 -> 0.717402 | E6: 71.74 | F6: MHS UBO Rates | Health.mil
A7: Limited oral evaluation – problem focused | B7: D0140 | C7: 0.93 | D7: =(C7*$E$5)/100 -> 1.076103 | E7: 107.61
A8: Oral evaluation for a patient under three years of age and counseling with primary caregiver | B8: D0145 | C8: 0.91 | D8: =(C8*$E$5)/100 -> 1.052961 | E8: 105.3
A9: Comprehensive oral evaluation – new or established patient | B9: D0150 | C9: 1.05 | D9: =(C9*$E$5)/100 -> 1.214955 | E9: 121.5
A10: Detailed and extensive oral evaluation – problem focused, by report | B10: D0160 | C10: 1.58 | D10: =(C10*$E$5)/100 -> 1.828218 | E10: 182.82
A11: Re‐evaluation – post-operative office visit | B11: D0171 | C11: 0.75 | D11: =(C11*$E$5)/100 -> 0.867825 | E11: 86.78
A12: Screening of a patient | B12: D0190 | C12: 0.5 | D12: =(C12*$E$5)/100 -> 0.57855 | E12: 57.86
A13: Intraoral - comprehensive series of radiographic images | B13: D0210 | C13: 1.64 | D13: =(C13*$E$5)/100 -> 1.897644 | E13: 189.77
A14: Intraoral – periapical first radiographic image | B14: D0220 | C14: 0.36 | D14: =(C14*$E$5)/100 -> 0.416556 | E14: 41.66
A15: Intraoral – periapical each additional radiographic image | B15: D0230 | C15: 0.3 | D15: =(C15*$E$5)/100 -> 0.34713 | E15: 34.71
A16: Intraoral – occlusal radiographic image | B16: D0240 | C16: 0.44 | D16: =(C16*$E$5)/100 -> 0.509124 | E16: 50.91
A17: Bitewing – single radiographic image | B17: D0270 | C17: 0.37 | D17: =(C17*$E$5)/100 -> 0.428127 | E17: 42.81
A18: Bitewings – two radiographic images | B18: D0272 | C18: 0.55 | D18: =(C18*$E$5)/100 -> 0.636405 | E18: 63.64
... A88: Patient treated | B88: W9999 | C88: 0 | D88: =(C88*$E$5)/100 -> 0 | E88: 0
E90: =D90*#REF! -> #REF!
E91: =D91*#REF! -> #REF!
A92: Total Dental
A93: Grand Total

Sheet Day1
A1: Date: | B1: 45806
A2: Operational Workload, Utilizing Relative Value Units (RVUs)
A3: Exercise: | B3: IRT FY25 Puerto Rico
A4: Site Location: | W4: Total Procedures: | Y4: =Z178 -> 0 | AC4: CY2024 RVU Conversion Factor Medical: | AD4: =SourceValues!E5 -> 115.71
A5: Procedure | B5: CPT | C5: Provider | D5: Provider | E5: Provider | F5: Provider | G5: Provider | H5: Provider | I5: Provider | J5: Provider | K5: Provider | L5: Provider | M5: Provider | N5: Provider | O5: Provider | P5: Provider | Q5: Provider | R5: Provider | S5: Provider | T5: Provider | U5: Provider | V5: Provider | W5: =ProjectDetails!B35 -> USNR | X5: =ProjectDetails!B36 -> AFRC | Y5: USPHS | Z5: Total Procedures | AA5: Worked RVU | AB5: Non-Facility RVU | AC5: Global Value | AD5: Total Value
A6: Medical
A7: =[1]SourceValues!A7 -> Outpt visit - prob focused - physician - 20 min | B7: =[1]SourceValues!B7 -> 99202 | Z7: =SUM(W7:Y7) -> 0 | AA7: =[1]SourceValues!C7 -> 0.93 | AB7: =[1]SourceValues!D7 -> 2.14 | AC7: =[1]SourceValues!E7 -> 69.3574
A8: =[1]SourceValues!A8 -> Outpt visit - prob focused - physician - 30 min | B8: =[1]SourceValues!B8 -> 99203 | Z8: =SUM(W8:Y8) -> 0 | AA8: =[1]SourceValues!C8 -> 1.42 | AB8: =[1]SourceValues!D8 -> 3.03 | AC8: =[1]SourceValues!E8 -> 98.2023
A9: =[1]SourceValues!A9 -> Outpt visit - prob focused - physician - 45 min | B9: =[1]SourceValues!B9 -> 99204 | Z9: =SUM(W9:Y9) -> 0 | AA9: =[1]SourceValues!C9 -> 2.43 | AB9: =[1]SourceValues!D9 -> 4.63 | AC9: =[1]SourceValues!E9 -> 150.0583
A10: =[1]SourceValues!A10 -> Cerumen evacuation | B10: =[1]SourceValues!B10 -> 69210 | Z10: =SUM(W10:Y10) -> 0 | AA10: =[1]SourceValues!C10 -> 0.61 | AB10: =[1]SourceValues!D10 -> 1.36 | AC10: =[1]SourceValues!E10 -> 44.0776
A11: =[1]SourceValues!A11 -> Counseling, prev med , 15 min | B11: =[1]SourceValues!B11 -> 99401 | Z11: =SUM(W11:Y11) -> 0 | AA11: =[1]SourceValues!C11 -> 0.48 | AB11: =[1]SourceValues!D11 -> 1.12 | AC11: =[1]SourceValues!E11 -> 36.2992
A12: =[1]SourceValues!A12 -> Counseling, prev med, 30 min | B12: =[1]SourceValues!B12 -> 99402 | Z12: =SUM(W12:Y12) -> 0 | AA12: =[1]SourceValues!C12 -> 0.98 | AB12: =[1]SourceValues!D12 -> 1.85 | AC12: =[1]SourceValues!E12 -> 59.9585
A13: =[1]SourceValues!A13 -> Counseling, smoking cessation, < 10 min | B13: =[1]SourceValues!B13 -> 99406 | Z13: =SUM(W13:Y13) -> 0 | AA13: =[1]SourceValues!C13 -> 0.24 | AB13: =[1]SourceValues!D13 -> 0.43 | AC13: =[1]SourceValues!E13 -> 13.9363
A14: =[1]SourceValues!A14 -> Counseling, smoking cessation, > 10 min | B14: =[1]SourceValues!B14 -> 99407 | Z14: =SUM(W14:Y14) -> 0 | AA14: =[1]SourceValues!C14 -> 0.5 | AB14: =[1]SourceValues!D14 -> 0.82 | AC14: =[1]SourceValues!E14 -> 26.5762
A15: =[1]SourceValues!A15 -> Multi-System complaint | B15: =[1]SourceValues!B15 -> 99214 | Z15: =SUM(W15:Y15) -> 0 | AA15: =[1]SourceValues!C15 -> 1.5 | AB15: =[1]SourceValues!D15 -> 3.06 | AC15: =[1]SourceValues!E15 -> 99.1746
A16: =[1]SourceValues!A16 -> Regular office visit | B16: =[1]SourceValues!B16 -> 99213 | Z16: =SUM(W16:Y16) -> 0 | AA16: =[1]SourceValues!C16 -> 0.97 | AB16: =[1]SourceValues!D16 -> 2.09 | AC16: =[1]SourceValues!E16 -> 67.7369
A17: =[1]SourceValues!A17 -> Wellness Visit under 1yr New PT | B17: =[1]SourceValues!B17 -> 99381 | Z17: =SUM(W17:Y17) -> 0 | AA17: =[1]SourceValues!C17 -> 1.5 | AB17: =[1]SourceValues!D17 -> 3.06 | AC17: =[1]SourceValues!E17 -> 99.1746
A18: =[1]SourceValues!A18 -> Wellness Visit 1-4 yrs new PT | B18: =[1]SourceValues!B18 -> 99382 | Z18: =SUM(W18:Y18) -> 0 | AA18: =[1]SourceValues!C18 -> 1.6 | AB18: =[1]SourceValues!D18 -> 3.28 | AC18: =[1]SourceValues!E18 -> 106.3048
... A55: =[1]SourceValues!A55 -> #REF! | B55: =[1]SourceValues!B55 -> #REF! | Z55: =SUM(W55:Y55) -> 0 | AA55: =[1]SourceValues!C55 -> #REF! | AB55: =[1]SourceValues!D55 -> #REF! | AC55: =[1]SourceValues!E55 -> 0
A56: =[1]SourceValues!A56 -> #REF! | B56: =[1]SourceValues!B56 -> #REF! | W56: =SUM(W7:W55) -> 0 | X56: =SUM(X7:X55) -> 0 | Y56: =SUM(Y7:Y55) -> 0 | Z56: =SUM(W56:Y56) -> 0 | AA56: =[1]SourceValues!C56 -> #REF! | AB56: =[1]SourceValues!D56 -> #REF! | AC56: =[1]SourceValues!E56 -> 0
A57: =[1]SourceValues!A57 -> Total Eye
A58: =[1]SourceValues!A58 -> Dental | B58: =[1]SourceValues!B58 -> #REF! | Z58: =SUM(W58:Y58) -> 0 | AA58: =[1]SourceValues!C58 -> #REF! | AB58: =[1]SourceValues!D58 -> #REF! | AC58: =[1]SourceValues!E58 -> #REF!
A59: =[1]SourceValues!A59 -> Limited oral evaluation | B59: =[1]SourceValues!B59 -> D0140 | Z59: =SUM(W59:Y59) -> 0 | AA59: =[1]SourceValues!C59 -> 0.75 | AB59: =[1]SourceValues!D59 -> 0.243075 | AC59: =[1]SourceValues!E59 -> 7.8780607
A60: =[1]SourceValues!A60 -> Comprehensive oral evaluation | B60: =[1]SourceValues!B60 -> D0150 | Z60: =SUM(W60:Y60) -> 0 | AA60: =[1]SourceValues!C60 -> 0.84 | AB60: =[1]SourceValues!D60 -> 0.272244 | AC60: =[1]SourceValues!E60 -> 8.823428
A61: =[1]SourceValues!A61 -> Detailed/extensive oral evaluation(oral cancer screening) | B61: =[1]SourceValues!B61 -> D0160 | Z61: =SUM(W61:Y61) -> 0 | AA61: =[1]SourceValues!C61 -> 1.38 | AB61: =[1]SourceValues!D61 -> 0.447258 | AC61: =[1]SourceValues!E61 -> 14.495632
A62: =[1]SourceValues!A62 -> Extraction, coronal rem - deciduous tooth | B62: =[1]SourceValues!B62 -> D7111 | Z62: =SUM(W62:Y62) -> 0 | AA62: =[1]SourceValues!C62 -> 1.17 | AB62: =[1]SourceValues!D62 -> 0.379197 | AC62: =[1]SourceValues!E62 -> 12.289775
A63: =[1]SourceValues!A63 -> Extraction, single tooth | B63: =[1]SourceValues!B63 -> D7140 | Z63: =SUM(W63:Y63) -> 0 | AA63: =[1]SourceValues!C63 -> 1.63 | AB63: =[1]SourceValues!D63 -> 0.528283 | AC63: =[1]SourceValues!E63 -> 17.121652
A64: =[1]SourceValues!A64 -> Surgical removal of erupted tooth | B64: =[1]SourceValues!B64 -> D7210 | Z64: =SUM(W64:Y64) -> 0 | AA64: =[1]SourceValues!C64 -> 2.76 | AB64: =[1]SourceValues!D64 -> 0.894516 | AC64: =[1]SourceValues!E64 -> 28.991264
A65: =[1]SourceValues!A65 -> Ext impacted tooth soft tissue | B65: =[1]SourceValues!B65 -> D7220 | Z65: =SUM(W65:Y65) -> 0 | AA65: =[1]SourceValues!C65 -> 3.26 | AB65: =[1]SourceValues!D65 -> 1.056566 | AC65: =[1]SourceValues!E65 -> 34.243304
A66: =[1]SourceValues!A66 -> Ext impacted tooth partial bony | B66: =[1]SourceValues!B66 -> D7230 | Z66: =SUM(W66:Y66) -> 0 | AA66: =[1]SourceValues!C66 -> 4.09 | AB66: =[1]SourceValues!D66 -> 1.325569 | AC66: =[1]SourceValues!E66 -> 42.961691
A67: =[1]SourceValues!A67 -> Ext impacted tooth comp bony | B67: =[1]SourceValues!B67 -> D7240 | Z67: =SUM(W67:Y67) -> 0 | AA67: =[1]SourceValues!C67 -> 4.84 | AB67: =[1]SourceValues!D67 -> 1.568644 | AC67: =[1]SourceValues!E67 -> 50.839752
A68: =[1]SourceValues!A68 -> Surgical removal of residual roots | B68: =[1]SourceValues!B68 -> D7250 | Z68: =SUM(W68:Y68) -> 0 | AA68: =[1]SourceValues!C68 -> 2.9 | AB68: =[1]SourceValues!D68 -> 0.93989 | AC68: =[1]SourceValues!E68 -> 30.461835
A69: =[1]SourceValues!A69 -> Alveoloplasty in conjunction with extractions-four or more teeth | B69: =[1]SourceValues!B69 -> D7310 | Z69: =SUM(W69:Y69) -> 0 | AA69: =[1]SourceValues!C69 -> 2.7 | AB69: =[1]SourceValues!D69 -> 0.87507 | AC69: =[1]SourceValues!E69 -> 28.361019
A70: =[1]SourceValues!A70 -> Alveoloplasty in conjunction with extractions-one to three teeth | B70: =[1]SourceValues!B70 -> D7311 | Z70: =SUM(W70:Y70) -> 0 | AA70: =[1]SourceValues!C70 -> 2.32 | AB70: =[1]SourceValues!D70 -> 0.751912 | AC70: =[1]SourceValues!E70 -> 24.369468
A71: =[1]SourceValues!A71 -> Cleaning of teeth | B71: =[1]SourceValues!B71 -> D1110 | W71: =SUM(W58:W70) -> 0 | X71: =SUM(X58:X70) -> 0 | Y71: =SUM(Y58:Y70) -> 0 | Z71: =SUM(W71:Y71) -> 0 | AA71: =[1]SourceValues!C71 -> 0.89 | AB71: =[1]SourceValues!D71 -> 0.288449 | AC71: =[1]SourceValues!E71 -> 9.3486321
A72: =[1]SourceValues!A72 -> Amalgam Filling-1 surface
A73: =[1]SourceValues!A73 -> Amalgam Filling-2 surface | B73: =[1]SourceValues!B73 -> D2150 | Z73: =SUM(W73:Y73) -> 0 | AA73: =[1]SourceValues!C73 -> 1.6 | AB73: =[1]SourceValues!D73 -> 0.51856 | AC73: =[1]SourceValues!E73 -> 16.80653
A74: =[1]SourceValues!A74 -> Amalgam Filling-3 surface | B74: =[1]SourceValues!B74 -> D2160 | Z74: =SUM(W74:Y74) -> 0 | AA74: =[1]SourceValues!C74 -> 1.95 | AB74: =[1]SourceValues!D74 -> 0.631995 | AC74: =[1]SourceValues!E74 -> 20.482958
A75: =[1]SourceValues!A75 -> Amalgam Filling-4 surface | B75: =[1]SourceValues!B75 -> D2161 | Z75: =SUM(W75:Y75) -> 0 | AA75: =[1]SourceValues!C75 -> 2.29 | AB75: =[1]SourceValues!D75 -> 0.742189 | AC75: =[1]SourceValues!E75 -> 24.054345
A76: =[1]SourceValues!A76 -> Composite Filling Anterior-1 surface | B76: =[1]SourceValues!B76 -> D2330 | Z76: =SUM(W76:Y76) -> 0 | AA76: =[1]SourceValues!C76 -> 1.55 | AB76: =[1]SourceValues!D76 -> 0.502355 | AC76: =[1]SourceValues!E76 -> 16.281326
...

Sheet Day2
A1: Date: | B1: 45806
A2: Operational Workload, Utilizing Relative Value Units (RVUs)
A3: Exercise: | B3: IRT FY25 Puerto Rico
A4: Site Location: | W4: Total Procedures: | Y4: =Z178 -> 0 | AC4: CY2024 RVU Conversion Factor Medical: | AD4: =SourceValues!E5 -> 115.71
A5: Procedure | B5: CPT | C5: Provider | D5: Provider | E5: Provider | F5: Provider | G5: Provider | H5: Provider | I5: Provider | J5: Provider | K5: Provider | L5: Provider | M5: Provider | N5: Provider | O5: Provider | P5: Provider | Q5: Provider | R5: Provider | S5: Provider | T5: Provider | U5: Provider | V5: Provider | W5: =ProjectDetails!B35 -> USNR | X5: =ProjectDetails!B36 -> AFRC | Y5: USPHS | Z5: Total Procedures | AA5: Worked RVU | AB5: Non-Facility RVU | AC5: Global Value | AD5: Total Value
A6: Medical
A7: =[1]SourceValues!A7 -> Outpt visit - prob focused - physician - 20 min | B7: =[1]SourceValues!B7 -> 99202 | Z7: =SUM(W7:Y7) -> 0 | AA7: =[1]SourceValues!C7 -> 0.93 | AB7: =[1]SourceValues!D7 -> 2.14 | AC7: =[1]SourceValues!E7 -> 69.3574
A8: =[1]SourceValues!A8 -> Outpt visit - prob focused - physician - 30 min | B8: =[1]SourceValues!B8 -> 99203 | Z8: =SUM(W8:Y8) -> 0 | AA8: =[1]SourceValues!C8 -> 1.42 | AB8: =[1]SourceValues!D8 -> 3.03 | AC8: =[1]SourceValues!E8 -> 98.2023
A9: =[1]SourceValues!A9 -> Outpt visit - prob focused - physician - 45 min | B9: =[1]SourceValues!B9 -> 99204 | Z9: =SUM(W9:Y9) -> 0 | AA9: =[1]SourceValues!C9 -> 2.43 | AB9: =[1]SourceValues!D9 -> 4.63 | AC9: =[1]SourceValues!E9 -> 150.0583
A10: =[1]SourceValues!A10 -> Cerumen evacuation | B10: =[1]SourceValues!B10 -> 69210 | Z10: =SUM(W10:Y10) -> 0 | AA10: =[1]SourceValues!C10 -> 0.61 | AB10: =[1]SourceValues!D10 -> 1.36 | AC10: =[1]SourceValues!E10 -> 44.0776
A11: =[1]SourceValues!A11 -> Counseling, prev med , 15 min | B11: =[1]SourceValues!B11 -> 99401 | Z11: =SUM(W11:Y11) -> 0 | AA11: =[1]SourceValues!C11 -> 0.48 | AB11: =[1]SourceValues!D11 -> 1.12 | AC11: =[1]SourceValues!E11 -> 36.2992
A12: =[1]SourceValues!A12 -> Counseling, prev med, 30 min | B12: =[1]SourceValues!B12 -> 99402 | Z12: =SUM(W12:Y12) -> 0 | AA12: =[1]SourceValues!C12 -> 0.98 | AB12: =[1]SourceValues!D12 -> 1.85 | AC12: =[1]SourceValues!E12 -> 59.9585
A13: =[1]SourceValues!A13 -> Counseling, smoking cessation, < 10 min | B13: =[1]SourceValues!B13 -> 99406 | Z13: =SUM(W13:Y13) -> 0 | AA13: =[1]SourceValues!C13 -> 0.24 | AB13: =[1]SourceValues!D13 -> 0.43 | AC13: =[1]SourceValues!E13 -> 13.9363
A14: =[1]SourceValues!A14 -> Counseling, smoking cessation, > 10 min | B14: =[1]SourceValues!B14 -> 99407 | Z14: =SUM(W14:Y14) -> 0 | AA14: =[1]SourceValues!C14 -> 0.5 | AB14: =[1]SourceValues!D14 -> 0.82 | AC14: =[1]SourceValues!E14 -> 26.5762
A15: =[1]SourceValues!A15 -> Multi-System complaint | B15: =[1]SourceValues!B15 -> 99214 | Z15: =SUM(W15:Y15) -> 0 | AA15: =[1]SourceValues!C15 -> 1.5 | AB15: =[1]SourceValues!D15 -> 3.06 | AC15: =[1]SourceValues!E15 -> 99.1746
A16: =[1]SourceValues!A16 -> Regular office visit | B16: =[1]SourceValues!B16 -> 99213 | Z16: =SUM(W16:Y16) -> 0 | AA16: =[1]SourceValues!C16 -> 0.97 | AB16: =[1]SourceValues!D16 -> 2.09 | AC16: =[1]SourceValues!E16 -> 67.7369
A17: =[1]SourceValues!A17 -> Wellness Visit under 1yr New PT | B17: =[1]SourceValues!B17 -> 99381 | Z17: =SUM(W17:Y17) -> 0 | AA17: =[1]SourceValues!C17 -> 1.5 | AB17: =[1]SourceValues!D17 -> 3.06 | AC17: =[1]SourceValues!E17 -> 99.1746
A18: =[1]SourceValues!A18 -> Wellness Visit 1-4 yrs new PT | B18: =[1]SourceValues!B18 -> 99382 | Z18: =SUM(W18:Y18) -> 0 | AA18: =[1]SourceValues!C18 -> 1.6 | AB18: =[1]SourceValues!D18 -> 3.28 | AC18: =[1]SourceValues!E18 -> 106.3048
... A55: =[1]SourceValues!A55 -> #REF! | B55: =[1]SourceValues!B55 -> #REF! | Z55: =SUM(W55:Y55) -> 0 | AA55: =[1]SourceValues!C55 -> #REF! | AB55: =[1]SourceValues!D55 -> #REF! | AC55: =[1]SourceValues!E55 -> 0
A56: =[1]SourceValues!A56 -> #REF! | B56: =[1]SourceValues!B56 -> #REF! | W56: =SUM(W7:W55) -> 0 | X56: =SUM(X7:X55) -> 0 | Y56: =SUM(Y7:Y55) -> 0 | Z56: =SUM(W56:Y56) -> 0 | AA56: =[1]SourceValues!C56 -> #REF! | AB56: =[1]SourceValues!D56 -> #REF! | AC56: =[1]SourceValues!E56 -> 0
A57: =[1]SourceValues!A57 -> Total Eye
A58: =[1]SourceValues!A58 -> Dental | B58: =[1]SourceValues!B58 -> #REF! | Z58: =SUM(W58:Y58) -> 0 | AA58: =[1]SourceValues!C58 -> #REF! | AB58: =[1]SourceValues!D58 -> #REF! | AC58: =[1]SourceValues!E58 -> #REF!
A59: =[1]SourceValues!A59 -> Limited oral evaluation | B59: =[1]SourceValues!B59 -> D0140 | Z59: =SUM(W59:Y59) -> 0 | AA59: =[1]SourceValues!C59 -> 0.75 | AB59: =[1]SourceValues!D59 -> 0.243075 | AC59: =[1]SourceValues!E59 -> 7.8780607
A60: =[1]SourceValues!A60 -> Comprehensive oral evaluation | B60: =[1]SourceValues!B60 -> D0150 | Z60: =SUM(W60:Y60) -> 0 | AA60: =[1]SourceValues!C60 -> 0.84 | AB60: =[1]SourceValues!D60 -> 0.272244 | AC60: =[1]SourceValues!E60 -> 8.823428
A61: =[1]SourceValues!A61 -> Detailed/extensive oral evaluation(oral cancer screening) | B61: =[1]SourceValues!B61 -> D0160 | Z61: =SUM(W61:Y61) -> 0 | AA61: =[1]SourceValues!C61 -> 1.38 | AB61: =[1]SourceValues!D61 -> 0.447258 | AC61: =[1]SourceValues!E61 -> 14.495632
A62: =[1]SourceValues!A62 -> Extraction, coronal rem - deciduous tooth | B62: =[1]SourceValues!B62 -> D7111 | Z62: =SUM(W62:Y62) -> 0 | AA62: =[1]SourceValues!C62 -> 1.17 | AB62: =[1]SourceValues!D62 -> 0.379197 | AC62: =[1]SourceValues!E62 -> 12.289775
A63: =[1]SourceValues!A63 -> Extraction, single tooth | B63: =[1]SourceValues!B63 -> D7140 | Z63: =SUM(W63:Y63) -> 0 | AA63: =[1]SourceValues!C63 -> 1.63 | AB63: =[1]SourceValues!D63 -> 0.528283 | AC63: =[1]SourceValues!E63 -> 17.121652
A64: =[1]SourceValues!A64 -> Surgical removal of erupted tooth | B64: =[1]SourceValues!B64 -> D7210 | Z64: =SUM(W64:Y64) -> 0 | AA64: =[1]SourceValues!C64 -> 2.76 | AB64: =[1]SourceValues!D64 -> 0.894516 | AC64: =[1]SourceValues!E64 -> 28.991264
A65: =[1]SourceValues!A65 -> Ext impacted tooth soft tissue | B65: =[1]SourceValues!B65 -> D7220 | Z65: =SUM(W65:Y65) -> 0 | AA65: =[1]SourceValues!C65 -> 3.26 | AB65: =[1]SourceValues!D65 -> 1.056566 | AC65: =[1]SourceValues!E65 -> 34.243304
A66: =[1]SourceValues!A66 -> Ext impacted tooth partial bony | B66: =[1]SourceValues!B66 -> D7230 | Z66: =SUM(W66:Y66) -> 0 | AA66: =[1]SourceValues!C66 -> 4.09 | AB66: =[1]SourceValues!D66 -> 1.325569 | AC66: =[1]SourceValues!E66 -> 42.961691
A67: =[1]SourceValues!A67 -> Ext impacted tooth comp bony | B67: =[1]SourceValues!B67 -> D7240 | Z67: =SUM(W67:Y67) -> 0 | AA67: =[1]SourceValues!C67 -> 4.84 | AB67: =[1]SourceValues!D67 -> 1.568644 | AC67: =[1]SourceValues!E67 -> 50.839752
A68: =[1]SourceValues!A68 -> Surgical removal of residual roots | B68: =[1]SourceValues!B68 -> D7250 | Z68: =SUM(W68:Y68) -> 0 | AA68: =[1]SourceValues!C68 -> 2.9 | AB68: =[1]SourceValues!D68 -> 0.93989 | AC68: =[1]SourceValues!E68 -> 30.461835
A69: =[1]SourceValues!A69 -> Alveoloplasty in conjunction with extractions-four or more teeth | B69: =[1]SourceValues!B69 -> D7310 | Z69: =SUM(W69:Y69) -> 0 | AA69: =[1]SourceValues!C69 -> 2.7 | AB69: =[1]SourceValues!D69 -> 0.87507 | AC69: =[1]SourceValues!E69 -> 28.361019
A70: =[1]SourceValues!A70 -> Alveoloplasty in conjunction with extractions-one to three teeth | B70: =[1]SourceValues!B70 -> D7311 | Z70: =SUM(W70:Y70) -> 0 | AA70: =[1]SourceValues!C70 -> 2.32 | AB70: =[1]SourceValues!D70 -> 0.751912 | AC70: =[1]SourceValues!E70 -> 24.369468
A71: =[1]SourceValues!A71 -> Cleaning of teeth | B71: =[1]SourceValues!B71 -> D1110 | W71: =SUM(W58:W70) -> 0 | X71: =SUM(X58:X70) -> 0 | Y71: =SUM(Y58:Y70) -> 0 | Z71: =SUM(W71:Y71) -> 0 | AA71: =[1]SourceValues!C71 -> 0.89 | AB71: =[1]SourceValues!D71 -> 0.288449 | AC71: =[1]SourceValues!E71 -> 9.3486321
A72: =[1]SourceValues!A72 -> Amalgam Filling-1 surface
A73: =[1]SourceValues!A73 -> Amalgam Filling-2 surface | B73: =[1]SourceValues!B73 -> D2150 | Z73: =SUM(W73:Y73) -> 0 | AA73: =[1]SourceValues!C73 -> 1.6 | AB73: =[1]SourceValues!D73 -> 0.51856 | AC73: =[1]SourceValues!E73 -> 16.80653
A74: =[1]SourceValues!A74 -> Amalgam Filling-3 surface | B74: =[1]SourceValues!B74 -> D2160 | Z74: =SUM(W74:Y74) -> 0 | AA74: =[1]SourceValues!C74 -> 1.95 | AB74: =[1]SourceValues!D74 -> 0.631995 | AC74: =[1]SourceValues!E74 -> 20.482958
A75: =[1]SourceValues!A75 -> Amalgam Filling-4 surface | B75: =[1]SourceValues!B75 -> D2161 | Z75: =SUM(W75:Y75) -> 0 | AA75: =[1]SourceValues!C75 -> 2.29 | AB75: =[1]SourceValues!D75 -> 0.742189 | AC75: =[1]SourceValues!E75 -> 24.054345
A76: =[1]SourceValues!A76 -> Composite Filling Anterior-1 surface | B76: =[1]SourceValues!B76 -> D2330 | Z76: =SUM(W76:Y76) -> 0 | AA76: =[1]SourceValues!C76 -> 1.55 | AB76: =[1]SourceValues!D76 -> 0.502355 | AC76: =[1]SourceValues!E76 -> 16.281326
...

Sheet Day3
A1: Date: | B1: 45806 | H1: 45806
A2: Operational Workload, Utilizing Relative Value Units (RVUs)
A3: Exercise: | B3: IRT FY25 Puerto Rico
A4: Site Location: | W4: Total Procedures: | Y4: =Z178 -> 0 | AC4: CY2024 RVU Conversion Factor Medical: | AD4: =SourceValues!E5 -> 115.71
A5: Procedure | B5: CPT | C5: Provider | D5: Provider | E5: Provider | F5: Provider | G5: Provider | H5: Provider | I5: Provider | J5: Provider | K5: Provider | L5: Provider | M5: Provider | N5: Provider | O5: Provider | P5: Provider | Q5: Provider | R5: Provider | S5: Provider | T5: Provider | U5: Provider | V5: Provider | W5: =ProjectDetails!B35 -> USNR | X5: =ProjectDetails!B36 -> AFRC | Y5: USPHS | Z5: Total Procedures | AA5: Worked RVU | AB5: Non-Facility RVU | AC5: Global Value | AD5: Total Value
A6: Medical
A7: =[1]SourceValues!A7 -> Outpt visit - prob focused - physician - 20 min | B7: =[1]SourceValues!B7 -> 99202 | Z7: =SUM(W7:Y7) -> 0 | AA7: =[1]SourceValues!C7 -> 0.93 | AB7: =[1]SourceValues!D7 -> 2.14 | AC7: =[1]SourceValues!E7 -> 69.3574
A8: =[1]SourceValues!A8 -> Outpt visit - prob focused - physician - 30 min | B8: =[1]SourceValues!B8 -> 99203 | Z8: =SUM(W8:Y8) -> 0 | AA8: =[1]SourceValues!C8 -> 1.42 | AB8: =[1]SourceValues!D8 -> 3.03 | AC8: =[1]SourceValues!E8 -> 98.2023
A9: =[1]SourceValues!A9 -> Outpt visit - prob focused - physician - 45 min | B9: =[1]SourceValues!B9 -> 99204 | Z9: =SUM(W9:Y9) -> 0 | AA9: =[1]SourceValues!C9 -> 2.43 | AB9: =[1]SourceValues!D9 -> 4.63 | AC9: =[1]SourceValues!E9 -> 150.0583
A10: =[1]SourceValues!A10 -> Cerumen evacuation | B10: =[1]SourceValues!B10 -> 69210 | Z10: =SUM(W10:Y10) -> 0 | AA10: =[1]SourceValues!C10 -> 0.61 | AB10: =[1]SourceValues!D10 -> 1.36 | AC10: =[1]SourceValues!E10 -> 44.0776
A11: =[1]SourceValues!A11 -> Counseling, prev med , 15 min | B11: =[1]SourceValues!B11 -> 99401 | Z11: =SUM(W11:Y11) -> 0 | AA11: =[1]SourceValues!C11 -> 0.48 | AB11: =[1]SourceValues!D11 -> 1.12 | AC11: =[1]SourceValues!E11 -> 36.2992
A12: =[1]SourceValues!A12 -> Counseling, prev med, 30 min | B12: =[1]SourceValues!B12 -> 99402 | Z12: =SUM(W12:Y12) -> 0 | AA12: =[1]SourceValues!C12 -> 0.98 | AB12: =[1]SourceValues!D12 -> 1.85 | AC12: =[1]SourceValues!E12 -> 59.9585
A13: =[1]SourceValues!A13 -> Counseling, smoking cessation, < 10 min | B13: =[1]SourceValues!B13 -> 99406 | Z13: =SUM(W13:Y13) -> 0 | AA13: =[1]SourceValues!C13 -> 0.24 | AB13: =[1]SourceValues!D13 -> 0.43 | AC13: =[1]SourceValues!E13 -> 13.9363
A14: =[1]SourceValues!A14 -> Counseling, smoking cessation, > 10 min | B14: =[1]SourceValues!B14 -> 99407 | Z14: =SUM(W14:Y14) -> 0 | AA14: =[1]SourceValues!C14 -> 0.5 | AB14: =[1]SourceValues!D14 -> 0.82 | AC14: =[1]SourceValues!E14 -> 26.5762
A15: =[1]SourceValues!A15 -> Multi-System complaint | B15: =[1]SourceValues!B15 -> 99214 | Z15: =SUM(W15:Y15) -> 0 | AA15: =[1]SourceValues!C15 -> 1.5 | AB15: =[1]SourceValues!D15 -> 3.06 | AC15: =[1]SourceValues!E15 -> 99.1746
A16: =[1]SourceValues!A16 -> Regular office visit | B16: =[1]SourceValues!B16 -> 99213 | Z16: =SUM(W16:Y16) -> 0 | AA16: =[1]SourceValues!C16 -> 0.97 | AB16: =[1]SourceValues!D16 -> 2.09 | AC16: =[1]SourceValues!E16 -> 67.7369
A17: =[1]SourceValues!A17 -> Wellness Visit under 1yr New PT | B17: =[1]SourceValues!B17 -> 99381 | Z17: =SUM(W17:Y17) -> 0 | AA17: =[1]SourceValues!C17 -> 1.5 | AB17: =[1]SourceValues!D17 -> 3.06 | AC17: =[1]SourceValues!E17 -> 99.1746
A18: =[1]SourceValues!A18 -> Wellness Visit 1-4 yrs new PT | B18: =[1]SourceValues!B18 -> 99382 | Z18: =SUM(W18:Y18) -> 0 | AA18: =[1]SourceValues!C18 -> 1.6 | AB18: =[1]SourceValues!D18 -> 3.28 | AC18: =[1]SourceValues!E18 -> 106.3048
... A55: =[1]SourceValues!A55 -> #REF! | B55: =[1]SourceValues!B55 -> #REF! | Z55: =SUM(W55:Y55) -> 0 | AA55: =[1]SourceValues!C55 -> #REF! | AB55: =[1]SourceValues!D55 -> #REF! | AC55: =[1]SourceValues!E55 -> 0
A56: =[1]SourceValues!A56 -> #REF! | B56: =[1]SourceValues!B56 -> #REF! | W56: =SUM(W7:W55) -> 0 | X56: =SUM(X7:X55) -> 0 | Y56: =SUM(Y7:Y55) -> 0 | Z56: =SUM(W56:Y56) -> 0 | AA56: =[1]SourceValues!C56 -> #REF! | AB56: =[1]SourceValues!D56 -> #REF! | AC56: =[1]SourceValues!E56 -> 0
A57: =[1]SourceValues!A57 -> Total Eye
A58: =[1]SourceValues!A58 -> Dental | B58: =[1]SourceValues!B58 -> #REF! | Z58: =SUM(W58:Y58) -> 0 | AA58: =[1]SourceValues!C58 -> #REF! | AB58: =[1]SourceValues!D58 -> #REF! | AC58: =[1]SourceValues!E58 -> #REF!
A59: =[1]SourceValues!A59 -> Limited oral evaluation | B59: =[1]SourceValues!B59 -> D0140 | Z59: =SUM(W59:Y59) -> 0 | AA59: =[1]SourceValues!C59 -> 0.75 | AB59: =[1]SourceValues!D59 -> 0.243075 | AC59: =[1]SourceValues!E59 -> 7.8780607
A60: =[1]SourceValues!A60 -> Comprehensive oral evaluation | B60: =[1]SourceValues!B60 -> D0150 | Z60: =SUM(W60:Y60) -> 0 | AA60: =[1]SourceValues!C60 -> 0.84 | AB60: =[1]SourceValues!D60 -> 0.272244 | AC60: =[1]SourceValues!E60 -> 8.823428
A61: =[1]SourceValues!A61 -> Detailed/extensive oral evaluation(oral cancer screening) | B61: =[1]SourceValues!B61 -> D0160 | Z61: =SUM(W61:Y61) -> 0 | AA61: =[1]SourceValues!C61 -> 1.38 | AB61: =[1]SourceValues!D61 -> 0.447258 | AC61: =[1]SourceValues!E61 -> 14.495632
A62: =[1]SourceValues!A62 -> Extraction, coronal rem - deciduous tooth | B62: =[1]SourceValues!B62 -> D7111 | Z62: =SUM(W62:Y62) -> 0 | AA62: =[1]SourceValues!C62 -> 1.17 | AB62: =[1]SourceValues!D62 -> 0.379197 | AC62: =[1]SourceValues!E62 -> 12.289775
A63: =[1]SourceValues!A63 -> Extraction, single tooth | B63: =[1]SourceValues!B63 -> D7140 | Z63: =SUM(W63:Y63) -> 0 | AA63: =[1]SourceValues!C63 -> 1.63 | AB63: =[1]SourceValues!D63 -> 0.528283 | AC63: =[1]SourceValues!E63 -> 17.121652
A64: =[1]SourceValues!A64 -> Surgical removal of erupted tooth | B64: =[1]SourceValues!B64 -> D7210 | Z64: =SUM(W64:Y64) -> 0 | AA64: =[1]SourceValues!C64 -> 2.76 | AB64: =[1]SourceValues!D64 -> 0.894516 | AC64: =[1]SourceValues!E64 -> 28.991264
A65: =[1]SourceValues!A65 -> Ext impacted tooth soft tissue | B65: =[1]SourceValues!B65 -> D7220 | Z65: =SUM(W65:Y65) -> 0 | AA65: =[1]SourceValues!C65 -> 3.26 | AB65: =[1]SourceValues!D65 -> 1.056566 | AC65: =[1]SourceValues!E65 -> 34.243304
A66: =[1]SourceValues!A66 -> Ext impacted tooth partial bony | B66: =[1]SourceValues!B66 -> D7230 | Z66: =SUM(W66:Y66) -> 0 | AA66: =[1]SourceValues!C66 -> 4.09 | AB66: =[1]SourceValues!D66 -> 1.325569 | AC66: =[1]SourceValues!E66 -> 42.961691
A67: =[1]SourceValues!A67 -> Ext impacted tooth comp bony | B67: =[1]SourceValues!B67 -> D7240 | Z67: =SUM(W67:Y67) -> 0 | AA67: =[1]SourceValues!C67 -> 4.84 | AB67: =[1]SourceValues!D67 -> 1.568644 | AC67: =[1]SourceValues!E67 -> 50.839752
A68: =[1]SourceValues!A68 -> Surgical removal of residual roots | B68: =[1]SourceValues!B68 -> D7250 | Z68: =SUM(W68:Y68) -> 0 | AA68: =[1]SourceValues!C68 -> 2.9 | AB68: =[1]SourceValues!D68 -> 0.93989 | AC68: =[1]SourceValues!E68 -> 30.461835
A69: =[1]SourceValues!A69 -> Alveoloplasty in conjunction with extractions-four or more teeth | B69: =[1]SourceValues!B69 -> D7310 | Z69: =SUM(W69:Y69) -> 0 | AA69: =[1]SourceValues!C69 -> 2.7 | AB69: =[1]SourceValues!D69 -> 0.87507 | AC69: =[1]SourceValues!E69 -> 28.361019
A70: =[1]SourceValues!A70 -> Alveoloplasty in conjunction with extractions-one to three teeth | B70: =[1]SourceValues!B70 -> D7311 | Z70: =SUM(W70:Y70) -> 0 | AA70: =[1]SourceValues!C70 -> 2.32 | AB70: =[1]SourceValues!D70 -> 0.751912 | AC70: =[1]SourceValues!E70 -> 24.369468
A71: =[1]SourceValues!A71 -> Cleaning of teeth | B71: =[1]SourceValues!B71 -> D1110 | W71: =SUM(W58:W70) -> 0 | X71: =SUM(X58:X70) -> 0 | Y71: =SUM(Y58:Y70) -> 0 | Z71: =SUM(W71:Y71) -> 0 | AA71: =[1]SourceValues!C71 -> 0.89 | AB71: =[1]SourceValues!D71 -> 0.288449 | AC71: =[1]SourceValues!E71 -> 9.3486321
A72: =[1]SourceValues!A72 -> Amalgam Filling-1 surface
A73: =[1]SourceValues!A73 -> Amalgam Filling-2 surface | B73: =[1]SourceValues!B73 -> D2150 | Z73: =SUM(W73:Y73) -> 0 | AA73: =[1]SourceValues!C73 -> 1.6 | AB73: =[1]SourceValues!D73 -> 0.51856 | AC73: =[1]SourceValues!E73 -> 16.80653
A74: =[1]SourceValues!A74 -> Amalgam Filling-3 surface | B74: =[1]SourceValues!B74 -> D2160 | Z74: =SUM(W74:Y74) -> 0 | AA74: =[1]SourceValues!C74 -> 1.95 | AB74: =[1]SourceValues!D74 -> 0.631995 | AC74: =[1]SourceValues!E74 -> 20.482958
A75: =[1]SourceValues!A75 -> Amalgam Filling-4 surface | B75: =[1]SourceValues!B75 -> D2161 | Z75: =SUM(W75:Y75) -> 0 | AA75: =[1]SourceValues!C75 -> 2.29 | AB75: =[1]SourceValues!D75 -> 0.742189 | AC75: =[1]SourceValues!E75 -> 24.054345
A76: =[1]SourceValues!A76 -> Composite Filling Anterior-1 surface | B76: =[1]SourceValues!B76 -> D2330 | Z76: =SUM(W76:Y76) -> 0 | AA76: =[1]SourceValues!C76 -> 1.55 | AB76: =[1]SourceValues!D76 -> 0.502355 | AC76: =[1]SourceValues!E76 -> 16.281326
...

Sheet Day4
A1: Date: | B1: 45806 | H1: 45806
A2: Operational Workload, Utilizing Relative Value Units (RVUs)
A3: Exercise: | B3: IRT FY25 Puerto Rico
A4: Site Location: | W4: Total Procedures: | Y4: =Z178 -> 0 | AC4: CY2024 RVU Conversion Factor Medical: | AD4: =SourceValues!E5 -> 115.71
A5: Procedure | B5: CPT | C5: Provider | D5: Provider | E5: Provider | F5: Provider | G5: Provider | H5: Provider | I5: Provider | J5: Provider | K5: Provider | L5: Provider | M5: Provider | N5: Provider | O5: Provider | P5: Provider | Q5: Provider | R5: Provider | S5: Provider | T5: Provider | U5: Provider | V5: Provider | W5: =ProjectDetails!B35 -> USNR | X5: =ProjectDetails!B36 -> AFRC | Y5: USPHS | Z5: Total Procedures | AA5: Worked RVU | AB5: Non-Facility RVU | AC5: Global Value | AD5: Total Value
A6: Medical
A7: =[1]SourceValues!A7 -> Outpt visit - prob focused - physician - 20 min | B7: =[1]SourceValues!B7 -> 99202 | Z7: =SUM(W7:Y7) -> 0 | AA7: =[1]SourceValues!C7 -> 0.93 | AB7: =[1]SourceValues!D7 -> 2.14 | AC7: =[1]SourceValues!E7 -> 69.3574
A8: =[1]SourceValues!A8 -> Outpt visit - prob focused - physician - 30 min | B8: =[1]SourceValues!B8 -> 99203 | Z8: =SUM(W8:Y8) -> 0 | AA8: =[1]SourceValues!C8 -> 1.42 | AB8: =[1]SourceValues!D8 -> 3.03 | AC8: =[1]SourceValues!E8 -> 98.2023
A9: =[1]SourceValues!A9 -> Outpt visit - prob focused - physician - 45 min | B9: =[1]SourceValues!B9 -> 99204 | Z9: =SUM(W9:Y9) -> 0 | AA9: =[1]SourceValues!C9 -> 2.43 | AB9: =[1]SourceValues!D9 -> 4.63 | AC9: =[1]SourceValues!E9 -> 150.0583
A10: =[1]SourceValues!A10 -> Cerumen evacuation | B10: =[1]SourceValues!B10 -> 69210 | Z10: =SUM(W10:Y10) -> 0 | AA10: =[1]SourceValues!C10 -> 0.61 | AB10: =[1]SourceValues!D10 -> 1.36 | AC10: =[1]SourceValues!E10 -> 44.0776
A11: =[1]SourceValues!A11 -> Counseling, prev med , 15 min | B11: =[1]SourceValues!B11 -> 99401 | Z11: =SUM(W11:Y11) -> 0 | AA11: =[1]SourceValues!C11 -> 0.48 | AB11: =[1]SourceValues!D11 -> 1.12 | AC11: =[1]SourceValues!E11 -> 36.2992
A12: =[1]SourceValues!A12 -> Counseling, prev med, 30 min | B12: =[1]SourceValues!B12 -> 99402 | Z12: =SUM(W12:Y12) -> 0 | AA12: =[1]SourceValues!C12 -> 0.98 | AB12: =[1]SourceValues!D12 -> 1.85 | AC12: =[1]SourceValues!E12 -> 59.9585
A13: =[1]SourceValues!A13 -> Counseling, smoking cessation, < 10 min | B13: =[1]SourceValues!B13 -> 99406 | Z13: =SUM(W13:Y13) -> 0 | AA13: =[1]SourceValues!C13 -> 0.24 | AB13: =[1]SourceValues!D13 -> 0.43 | AC13: =[1]SourceValues!E13 -> 13.9363
A14: =[1]SourceValues!A14 -> Counseling, smoking cessation, > 10 min | B14: =[1]SourceValues!B14 -> 99407 | Z14: =SUM(W14:Y14) -> 0 | AA14: =[1]SourceValues!C14 -> 0.5 | AB14: =[1]SourceValues!D14 -> 0.82 | AC14: =[1]SourceValues!E14 -> 26.5762
A15: =[1]SourceValues!A15 -> Multi-System complaint | B15: =[1]SourceValues!B15 -> 99214 | Z15: =SUM(W15:Y15) -> 0 | AA15: =[1]SourceValues!C15 -> 1.5 | AB15: =[1]SourceValues!D15 -> 3.06 | AC15: =[1]SourceValues!E15 -> 99.1746
A16: =[1]SourceValues!A16 -> Regular office visit | B16: =[1]SourceValues!B16 -> 99213 | Z16: =SUM(W16:Y16) -> 0 | AA16: =[1]SourceValues!C16 -> 0.97 | AB16: =[1]SourceValues!D16 -> 2.09 | AC16: =[1]SourceValues!E16 -> 67.7369
A17: =[1]SourceValues!A17 -> Wellness Visit under 1yr New PT | B17: =[1]SourceValues!B17 -> 99381 | Z17: =SUM(W17:Y17) -> 0 | AA17: =[1]SourceValues!C17 -> 1.5 | AB17: =[1]SourceValues!D17 -> 3.06 | AC17: =[1]SourceValues!E17 -> 99.1746
A18: =[1]SourceValues!A18 -> Wellness Visit 1-4 yrs new PT | B18: =[1]SourceValues!B18 -> 99382 | Z18: =SUM(W18:Y18) -> 0 | AA18: =[1]SourceValues!C18 -> 1.6 | AB18: =[1]SourceValues!D18 -> 3.28 | AC18: =[1]SourceValues!E18 -> 106.3048
... A55: =[1]SourceValues!A55 -> #REF! | B55: =[1]SourceValues!B55 -> #REF! | Z55: =SUM(W55:Y55) -> 0 | AA55: =[1]SourceValues!C55 -> #REF! | AB55: =[1]SourceValues!D55 -> #REF! | AC55: =[1]SourceValues!E55 -> 0
A56: =[1]SourceValues!A56 -> #REF! | B56: =[1]SourceValues!B56 -> #REF! | W56: =SUM(W7:W55) -> 0 | X56: =SUM(X7:X55) -> 0 | Y56: =SUM(Y7:Y55) -> 0 | Z56: =SUM(W56:Y56) -> 0 | AA56: =[1]SourceValues!C56 -> #REF! | AB56: =[1]SourceValues!D56 -> #REF! | AC56: =[1]SourceValues!E56 -> 0
A57: =[1]SourceValues!A57 -> Total Eye
A58: =[1]SourceValues!A58 -> Dental | B58: =[1]SourceValues!B58 -> #REF! | Z58: =SUM(W58:Y58) -> 0 | AA58: =[1]SourceValues!C58 -> #REF! | AB58: =[1]SourceValues!D58 -> #REF! | AC58: =[1]SourceValues!E58 -> #REF!
A59: =[1]SourceValues!A59 -> Limited oral evaluation | B59: =[1]SourceValues!B59 -> D0140 | Z59: =SUM(W59:Y59) -> 0 | AA59: =[1]SourceValues!C59 -> 0.75 | AB59: =[1]SourceValues!D59 -> 0.243075 | AC59: =[1]SourceValues!E59 -> 7.8780607
A60: =[1]SourceValues!A60 -> Comprehensive oral evaluation | B60: =[1]SourceValues!B60 -> D0150 | Z60: =SUM(W60:Y60) -> 0 | AA60: =[1]SourceValues!C60 -> 0.84 | AB60: =[1]SourceValues!D60 -> 0.272244 | AC60: =[1]SourceValues!E60 -> 8.823428
A61: =[1]SourceValues!A61 -> Detailed/extensive oral evaluation(oral cancer screening) | B61: =[1]SourceValues!B61 -> D0160 | Z61: =SUM(W61:Y61) -> 0 | AA61: =[1]SourceValues!C61 -> 1.38 | AB61: =[1]SourceValues!D61 -> 0.447258 | AC61: =[1]SourceValues!E61 -> 14.495632
A62: =[1]SourceValues!A62 -> Extraction, coronal rem - deciduous tooth | B62: =[1]SourceValues!B62 -> D7111 | Z62: =SUM(W62:Y62) -> 0 | AA62: =[1]SourceValues!C62 -> 1.17 | AB62: =[1]SourceValues!D62 -> 0.379197 | AC62: =[1]SourceValues!E62 -> 12.289775
A63: =[1]SourceValues!A63 -> Extraction, single tooth | B63: =[1]SourceValues!B63 -> D7140 | Z63: =SUM(W63:Y63) -> 0 | AA63: =[1]SourceValues!C63 -> 1.63 | AB63: =[1]SourceValues!D63 -> 0.528283 | AC63: =[1]SourceValues!E63 -> 17.121652
A64: =[1]SourceValues!A64 -> Surgical removal of erupted tooth | B64: =[1]SourceValues!B64 -> D7210 | Z64: =SUM(W64:Y64) -> 0 | AA64: =[1]SourceValues!C64 -> 2.76 | AB64: =[1]SourceValues!D64 -> 0.894516 | AC64: =[1]SourceValues!E64 -> 28.991264
A65: =[1]SourceValues!A65 -> Ext impacted tooth soft tissue | B65: =[1]SourceValues!B65 -> D7220 | Z65: =SUM(W65:Y65) -> 0 | AA65: =[1]SourceValues!C65 -> 3.26 | AB65: =[1]SourceValues!D65 -> 1.056566 | AC65: =[1]SourceValues!E65 -> 34.243304
A66: =[1]SourceValues!A66 -> Ext impacted tooth partial bony | B66: =[1]SourceValues!B66 -> D7230 | Z66: =SUM(W66:Y66) -> 0 | AA66: =[1]SourceValues!C66 -> 4.09 | AB66: =[1]SourceValues!D66 -> 1.325569 | AC66: =[1]SourceValues!E66 -> 42.961691
A67: =[1]SourceValues!A67 -> Ext impacted tooth comp bony | B67: =[1]SourceValues!B67 -> D7240 | Z67: =SUM(W67:Y67) -> 0 | AA67: =[1]SourceValues!C67 -> 4.84 | AB67: =[1]SourceValues!D67 -> 1.568644 | AC67: =[1]SourceValues!E67 -> 50.839752
A68: =[1]SourceValues!A68 -> Surgical removal of residual roots | B68: =[1]SourceValues!B68 -> D7250 | Z68: =SUM(W68:Y68) -> 0 | AA68: =[1]SourceValues!C68 -> 2.9 | AB68: =[1]SourceValues!D68 -> 0.93989 | AC68: =[1]SourceValues!E68 -> 30.461835
A69: =[1]SourceValues!A69 -> Alveoloplasty in conjunction with extractions-four or more teeth | B69: =[1]SourceValues!B69 -> D7310 | Z69: =SUM(W69:Y69) -> 0 | AA69: =[1]SourceValues!C69 -> 2.7 | AB69: =[1]SourceValues!D69 -> 0.87507 | AC69: =[1]SourceValues!E69 -> 28.361019
A70: =[1]SourceValues!A70 -> Alveoloplasty in conjunction with extractions-one to three teeth | B70: =[1]SourceValues!B70 -> D7311 | Z70: =SUM(W70:Y70) -> 0 | AA70: =[1]SourceValues!C70 -> 2.32 | AB70: =[1]SourceValues!D70 -> 0.751912 | AC70: =[1]SourceValues!E70 -> 24.369468
A71: =[1]SourceValues!A71 -> Cleaning of teeth | B71: =[1]SourceValues!B71 -> D1110 | W71: =SUM(W58:W70) -> 0 | X71: =SUM(X58:X70) -> 0 | Y71: =SUM(Y58:Y70) -> 0 | Z71: =SUM(W71:Y71) -> 0 | AA71: =[1]SourceValues!C71 -> 0.89 | AB71: =[1]SourceValues!D71 -> 0.288449 | AC71: =[1]SourceValues!E71 -> 9.3486321
A72: =[1]SourceValues!A72 -> Amalgam Filling-1 surface
A73: =[1]SourceValues!A73 -> Amalgam Filling-2 surface | B73: =[1]SourceValues!B73 -> D2150 | Z73: =SUM(W73:Y73) -> 0 | AA73: =[1]SourceValues!C73 -> 1.6 | AB73: =[1]SourceValues!D73 -> 0.51856 | AC73: =[1]SourceValues!E73 -> 16.80653
A74: =[1]SourceValues!A74 -> Amalgam Filling-3 surface | B74: =[1]SourceValues!B74 -> D2160 | Z74: =SUM(W74:Y74) -> 0 | AA74: =[1]SourceValues!C74 -> 1.95 | AB74: =[1]SourceValues!D74 -> 0.631995 | AC74: =[1]SourceValues!E74 -> 20.482958
A75: =[1]SourceValues!A75 -> Amalgam Filling-4 surface | B75: =[1]SourceValues!B75 -> D2161 | Z75: =SUM(W75:Y75) -> 0 | AA75: =[1]SourceValues!C75 -> 2.29 | AB75: =[1]SourceValues!D75 -> 0.742189 | AC75: =[1]SourceValues!E75 -> 24.054345
A76: =[1]SourceValues!A76 -> Composite Filling Anterior-1 surface | B76: =[1]SourceValues!B76 -> D2330 | Z76: =SUM(W76:Y76) -> 0 | AA76: =[1]SourceValues!C76 -> 1.55 | AB76: =[1]SourceValues!D76 -> 0.502355 | AC76: =[1]SourceValues!E76 -> 16.281326
...

Sheet Day5
A1: Date: | B1: 45806
A2: Operational Workload, Utilizing Relative Value Units (RVUs)
A3: Exercise: | B3: IRT FY25 Puerto Rico
A4: Site Location: | W4: Total Procedures: | Y4: =Z178 -> 0 | AC4: CY2024 RVU Conversion Factor Medical: | AD4: =SourceValues!E5 -> 115.71
A5: Procedure | B5: CPT | C5: Provider | D5: Provider | E5: Provider | F5: Provider | G5: Provider | H5: Provider | I5: Provider | J5: Provider | K5: Provider | L5: Provider | M5: Provider | N5: Provider | O5: Provider | P5: Provider | Q5: Provider | R5: Provider | S5: Provider | T5: Provider | U5: Provider | V5: Provider | W5: =ProjectDetails!B35 -> USNR | X5: =ProjectDetails!B36 -> AFRC | Y5: USPHS | Z5: Total Procedures | AA5: Worked RVU | AB5: Non-Facility RVU | AC5: Global Value | AD5: Total Value
A6: Medical
A7: =[1]SourceValues!A7 -> Outpt visit - prob focused - physician - 20 min | B7: =[1]SourceValues!B7 -> 99202 | Z7: =SUM(W7:Y7) -> 0 | AA7: =[1]SourceValues!C7 -> 0.93 | AB7: =[1]SourceValues!D7 -> 2.14 | AC7: =[1]SourceValues!E7 -> 69.3574
A8: =[1]SourceValues!A8 -> Outpt visit - prob focused - physician - 30 min | B8: =[1]SourceValues!B8 -> 99203 | Z8: =SUM(W8:Y8) -> 0 | AA8: =[1]SourceValues!C8 -> 1.42 | AB8: =[1]SourceValues!D8 -> 3.03 | AC8: =[1]SourceValues!E8 -> 98.2023
A9: =[1]SourceValues!A9 -> Outpt visit - prob focused - physician - 45 min | B9: =[1]SourceValues!B9 -> 99204 | Z9: =SUM(W9:Y9) -> 0 | AA9: =[1]SourceValues!C9 -> 2.43 | AB9: =[1]SourceValues!D9 -> 4.63 | AC9: =[1]SourceValues!E9 -> 150.0583
A10: =[1]SourceValues!A10 -> Cerumen evacuation | B10: =[1]SourceValues!B10 -> 69210 | Z10: =SUM(W10:Y10) -> 0 | AA10: =[1]SourceValues!C10 -> 0.61 | AB10: =[1]SourceValues!D10 -> 1.36 | AC10: =[1]SourceValues!E10 -> 44.0776
A11: =[1]SourceValues!A11 -> Counseling, prev med , 15 min | B11: =[1]SourceValues!B11 -> 99401 | Z11: =SUM(W11:Y11) -> 0 | AA11: =[1]SourceValues!C11 -> 0.48 | AB11: =[1]SourceValues!D11 -> 1.12 | AC11: =[1]SourceValues!E11 -> 36.2992
A12: =[1]SourceValues!A12 -> Counseling, prev med, 30 min | B12: =[1]SourceValues!B12 -> 99402 | Z12: =SUM(W12:Y12) -> 0 | AA12: =[1]SourceValues!C12 -> 0.98 | AB12: =[1]SourceValues!D12 -> 1.85 | AC12: =[1]SourceValues!E12 -> 59.9585
A13: =[1]SourceValues!A13 -> Counseling, smoking cessation, < 10 min | B13: =[1]SourceValues!B13 -> 99406 | Z13: =SUM(W13:Y13) -> 0 | AA13: =[1]SourceValues!C13 -> 0.24 | AB13: =[1]SourceValues!D13 -> 0.43 | AC13: =[1]SourceValues!E13 -> 13.9363
A14: =[1]SourceValues!A14 -> Counseling, smoking cessation, > 10 min | B14: =[1]SourceValues!B14 -> 99407 | Z14: =SUM(W14:Y14) -> 0 | AA14: =[1]SourceValues!C14 -> 0.5 | AB14: =[1]SourceValues!D14 -> 0.82 | AC14: =[1]SourceValues!E14 -> 26.5762
A15: =[1]SourceValues!A15 -> Multi-System complaint | B15: =[1]SourceValues!B15 -> 99214 | Z15: =SUM(W15:Y15) -> 0 | AA15: =[1]SourceValues!C15 -> 1.5 | AB15: =[1]SourceValues!D15 -> 3.06 | AC15: =[1]SourceValues!E15 -> 99.1746
A16: =[1]SourceValues!A16 -> Regular office visit | B16: =[1]SourceValues!B16 -> 99213 | Z16: =SUM(W16:Y16) -> 0 | AA16: =[1]SourceValues!C16 -> 0.97 | AB16: =[1]SourceValues!D16 -> 2.09 | AC16: =[1]SourceValues!E16 -> 67.7369
A17: =[1]SourceValues!A17 -> Wellness Visit under 1yr New PT | B17: =[1]SourceValues!B17 -> 99381 | Z17: =SUM(W17:Y17) -> 0 | AA17: =[1]SourceValues!C17 -> 1.5 | AB17: =[1]SourceValues!D17 -> 3.06 | AC17: =[1]SourceValues!E17 -> 99.1746
A18: =[1]SourceValues!A18 -> Wellness Visit 1-4 yrs new PT | B18: =[1]SourceValues!B18 -> 99382 | Z18: =SUM(W18:Y18) -> 0 | AA18: =[1]SourceValues!C18 -> 1.6 | AB18: =[1]SourceValues!D18 -> 3.28 | AC18: =[1]SourceValues!E18 -> 106.3048
... A55: =[1]SourceValues!A55 -> #REF! | B55: =[1]SourceValues!B55 -> #REF! | Z55: =SUM(W55:Y55) -> 0 | AA55: =[1]SourceValues!C55 -> #REF! | AB55: =[1]SourceValues!D55 -> #REF! | AC55: =[1]SourceValues!E55 -> 0
A56: =[1]SourceValues!A56 -> #REF! | B56: =[1]SourceValues!B56 -> #REF! | W56: =SUM(W7:W55) -> 0 | X56: =SUM(X7:X55) -> 0 | Y56: =SUM(Y7:Y55) -> 0 | Z56: =SUM(W56:Y56) -> 0 | AA56: =[1]SourceValues!C56 -> #REF! | AB56: =[1]SourceValues!D56 -> #REF! | AC56: =[1]SourceValues!E56 -> 0
A57: =[1]SourceValues!A57 -> Total Eye
A58: =[1]SourceValues!A58 -> Dental | B58: =[1]SourceValues!B58 -> #REF! | Z58: =SUM(W58:Y58) -> 0 | AA58: =[1]SourceValues!C58 -> #REF! | AB58: =[1]SourceValues!D58 -> #REF! | AC58: =[1]SourceValues!E58 -> #REF!
A59: =[1]SourceValues!A59 -> Limited oral evaluation | B59: =[1]SourceValues!B59 -> D0140 | Z59: =SUM(W59:Y59) -> 0 | AA59: =[1]SourceValues!C59 -> 0.75 | AB59: =[1]SourceValues!D59 -> 0.243075 | AC59: =[1]SourceValues!E59 -> 7.8780607
A60: =[1]SourceValues!A60 -> Comprehensive oral evaluation | B60: =[1]SourceValues!B60 -> D0150 | Z60: =SUM(W60:Y60) -> 0 | AA60: =[1]SourceValues!C60 -> 0.84 | AB60: =[1]SourceValues!D60 -> 0.272244 | AC60: =[1]SourceValues!E60 -> 8.823428
A61: =[1]SourceValues!A61 -> Detailed/extensive oral evaluation(oral cancer screening) | B61: =[1]SourceValues!B61 -> D0160 | Z61: =SUM(W61:Y61) -> 0 | AA61: =[1]SourceValues!C61 -> 1.38 | AB61: =[1]SourceValues!D61 -> 0.447258 | AC61: =[1]SourceValues!E61 -> 14.495632
A62: =[1]SourceValues!A62 -> Extraction, coronal rem - deciduous tooth | B62: =[1]SourceValues!B62 -> D7111 | Z62: =SUM(W62:Y62) -> 0 | AA62: =[1]SourceValues!C62 -> 1.17 | AB62: =[1]SourceValues!D62 -> 0.379197 | AC62: =[1]SourceValues!E62 -> 12.289775
A63: =[1]SourceValues!A63 -> Extraction, single tooth | B63: =[1]SourceValues!B63 -> D7140 | Z63: =SUM(W63:Y63) -> 0 | AA63: =[1]SourceValues!C63 -> 1.63 | AB63: =[1]SourceValues!D63 -> 0.528283 | AC63: =[1]SourceValues!E63 -> 17.121652
A64: =[1]SourceValues!A64 -> Surgical removal of erupted tooth | B64: =[1]SourceValues!B64 -> D7210 | Z64: =SUM(W64:Y64) -> 0 | AA64: =[1]SourceValues!C64 -> 2.76 | AB64: =[1]SourceValues!D64 -> 0.894516 | AC64: =[1]SourceValues!E64 -> 28.991264
A65: =[1]SourceValues!A65 -> Ext impacted tooth soft tissue | B65: =[1]SourceValues!B65 -> D7220 | Z65: =SUM(W65:Y65) -> 0 | AA65: =[1]SourceValues!C65 -> 3.26 | AB65: =[1]SourceValues!D65 -> 1.056566 | AC65: =[1]SourceValues!E65 -> 34.243304
A66: =[1]SourceValues!A66 -> Ext impacted tooth partial bony | B66: =[1]SourceValues!B66 -> D7230 | Z66: =SUM(W66:Y66) -> 0 | AA66: =[1]SourceValues!C66 -> 4.09 | AB66: =[1]SourceValues!D66 -> 1.325569 | AC66: =[1]SourceValues!E66 -> 42.961691
A67: =[1]SourceValues!A67 -> Ext impacted tooth comp bony | B67: =[1]SourceValues!B67 -> D7240 | Z67: =SUM(W67:Y67) -> 0 | AA67: =[1]SourceValues!C67 -> 4.84 | AB67: =[1]SourceValues!D67 -> 1.568644 | AC67: =[1]SourceValues!E67 -> 50.839752
A68: =[1]SourceValues!A68 -> Surgical removal of residual roots | B68: =[1]SourceValues!B68 -> D7250 | Z68: =SUM(W68:Y68) -> 0 | AA68: =[1]SourceValues!C68 -> 2.9 | AB68: =[1]SourceValues!D68 -> 0.93989 | AC68: =[1]SourceValues!E68 -> 30.461835
A69: =[1]SourceValues!A69 -> Alveoloplasty in conjunction with extractions-four or more teeth | B69: =[1]SourceValues!B69 -> D7310 | Z69: =SUM(W69:Y69) -> 0 | AA69: =[1]SourceValues!C69 -> 2.7 | AB69: =[1]SourceValues!D69 -> 0.87507 | AC69: =[1]SourceValues!E69 -> 28.361019
A70: =[1]SourceValues!A70 -> Alveoloplasty in conjunction with extractions-one to three teeth | B70: =[1]SourceValues!B70 -> D7311 | Z70: =SUM(W70:Y70) -> 0 | AA70: =[1]SourceValues!C70 -> 2.32 | AB70: =[1]SourceValues!D70 -> 0.751912 | AC70: =[1]SourceValues!E70 -> 24.369468
A71: =[1]SourceValues!A71 -> Cleaning of teeth | B71: =[1]SourceValues!B71 -> D1110 | W71: =SUM(W58:W70) -> 0 | X71: =SUM(X58:X70) -> 0 | Y71: =SUM(Y58:Y70) -> 0 | Z71: =SUM(W71:Y71) -> 0 | AA71: =[1]SourceValues!C71 -> 0.89 | AB71: =[1]SourceValues!D71 -> 0.288449 | AC71: =[1]SourceValues!E71 -> 9.3486321
A72: =[1]SourceValues!A72 -> Amalgam Filling-1 surface
A73: =[1]SourceValues!A73 -> Amalgam Filling-2 surface | B73: =[1]SourceValues!B73 -> D2150 | Z73: =SUM(W73:Y73) -> 0 | AA73: =[1]SourceValues!C73 -> 1.6 | AB73: =[1]SourceValues!D73 -> 0.51856 | AC73: =[1]SourceValues!E73 -> 16.80653
A74: =[1]SourceValues!A74 -> Amalgam Filling-3 surface | B74: =[1]SourceValues!B74 -> D2160 | Z74: =SUM(W74:Y74) -> 0 | AA74: =[1]SourceValues!C74 -> 1.95 | AB74: =[1]SourceValues!D74 -> 0.631995 | AC74: =[1]SourceValues!E74 -> 20.482958
A75: =[1]SourceValues!A75 -> Amalgam Filling-4 surface | B75: =[1]SourceValues!B75 -> D2161 | Z75: =SUM(W75:Y75) -> 0 | AA75: =[1]SourceValues!C75 -> 2.29 | AB75: =[1]SourceValues!D75 -> 0.742189 | AC75: =[1]SourceValues!E75 -> 24.054345
A76: =[1]SourceValues!A76 -> Composite Filling Anterior-1 surface | B76: =[1]SourceValues!B76 -> D2330 | Z76: =SUM(W76:Y76) -> 0 | AA76: =[1]SourceValues!C76 -> 1.55 | AB76: =[1]SourceValues!D76 -> 0.502355 | AC76: =[1]SourceValues!E76 -> 16.281326
...

Sheet Day6
A1: Date: | B1: 45806
A2: Operational Workload, Utilizing Relative Value Units (RVUs)
A3: Exercise: | B3: IRT FY25 Puerto Rico
A4: Site Location: | W4: Total Procedures: | Y4: =Z178 -> 0 | AC4: CY2024 RVU Conversion Factor Medical: | AD4: =SourceValues!E5 -> 115.71
A5: Procedure | B5: CPT | C5: Provider | D5: Provider | E5: Provider | F5: Provider | G5: Provider | H5: Provider | I5: Provider | J5: Provider | K5: Provider | L5: Provider | M5: Provider | N5: Provider | O5: Provider | P5: Provider | Q5: Provider | R5: Provider | S5: Provider | T5: Provider | U5: Provider | V5: Provider | W5: =ProjectDetails!B35 -> USNR | X5: =ProjectDetails!B36 -> AFRC | Y5: USPHS | Z5: Total Procedures | AA5: Worked RVU | AB5: Non-Facility RVU | AC5: Global Value | AD5: Total Value
A6: Medical
A7: =[1]SourceValues!A7 -> Outpt visit - prob focused - physician - 20 min | B7: =[1]SourceValues!B7 -> 99202 | Z7: =SUM(W7:Y7) -> 0 | AA7: =[1]SourceValues!C7 -> 0.93 | AB7: =[1]SourceValues!D7 -> 2.14 | AC7: =[1]SourceValues!E7 -> 69.3574
A8: =[1]SourceValues!A8 -> Outpt visit - prob focused - physician - 30 min | B8: =[1]SourceValues!B8 -> 99203 | Z8: =SUM(W8:Y8) -> 0 | AA8: =[1]SourceValues!C8 -> 1.42 | AB8: =[1]SourceValues!D8 -> 3.03 | AC8: =[1]SourceValues!E8 -> 98.2023
A9: =[1]SourceValues!A9 -> Outpt visit - prob focused - physician - 45 min | B9: =[1]SourceValues!B9 -> 99204 | Z9: =SUM(W9:Y9) -> 0 | AA9: =[1]SourceValues!C9 -> 2.43 | AB9: =[1]SourceValues!D9 -> 4.63 | AC9: =[1]SourceValues!E9 -> 150.0583
A10: =[1]SourceValues!A10 -> Cerumen evacuation | B10: =[1]SourceValues!B10 -> 69210 | Z10: =SUM(W10:Y10) -> 0 | AA10: =[1]SourceValues!C10 -> 0.61 | AB10: =[1]SourceValues!D10 -> 1.36 | AC10: =[1]SourceValues!E10 -> 44.0776
A11: =[1]SourceValues!A11 -> Counseling, prev med , 15 min | B11: =[1]SourceValues!B11 -> 99401 | Z11: =SUM(W11:Y11) -> 0 | AA11: =[1]SourceValues!C11 -> 0.48 | AB11: =[1]SourceValues!D11 -> 1.12 | AC11: =[1]SourceValues!E11 -> 36.2992
A12: =[1]SourceValues!A12 -> Counseling, prev med, 30 min | B12: =[1]SourceValues!B12 -> 99402 | Z12: =SUM(W12:Y12) -> 0 | AA12: =[1]SourceValues!C12 -> 0.98 | AB12: =[1]SourceValues!D12 -> 1.85 | AC12: =[1]SourceValues!E12 -> 59.9585
A13: =[1]SourceValues!A13 -> Counseling, smoking cessation, < 10 min | B13: =[1]SourceValues!B13 -> 99406 | Z13: =SUM(W13:Y13) -> 0 | AA13: =[1]SourceValues!C13 -> 0.24 | AB13: =[1]SourceValues!D13 -> 0.43 | AC13: =[1]SourceValues!E13 -> 13.9363
A14: =[1]SourceValues!A14 -> Counseling, smoking cessation, > 10 min | B14: =[1]SourceValues!B14 -> 99407 | Z14: =SUM(W14:Y14) -> 0 | AA14: =[1]SourceValues!C14 -> 0.5 | AB14: =[1]SourceValues!D14 -> 0.82 | AC14: =[1]SourceValues!E14 -> 26.5762
A15: =[1]SourceValues!A15 -> Multi-System complaint | B15: =[1]SourceValues!B15 -> 99214 | Z15: =SUM(W15:Y15) -> 0 | AA15: =[1]SourceValues!C15 -> 1.5 | AB15: =[1]SourceValues!D15 -> 3.06 | AC15: =[1]SourceValues!E15 -> 99.1746
A16: =[1]SourceValues!A16 -> Regular office visit | B16: =[1]SourceValues!B16 -> 99213 | Z16: =SUM(W16:Y16) -> 0 | AA16: =[1]SourceValues!C16 -> 0.97 | AB16: =[1]SourceValues!D16 -> 2.09 | AC16: =[1]SourceValues!E16 -> 67.7369
A17: =[1]SourceValues!A17 -> Wellness Visit under 1yr New PT | B17: =[1]SourceValues!B17 -> 99381 | Z17: =SUM(W17:Y17) -> 0 | AA17: =[1]SourceValues!C17 -> 1.5 | AB17: =[1]SourceValues!D17 -> 3.06 | AC17: =[1]SourceValues!E17 -> 99.1746
A18: =[1]SourceValues!A18 -> Wellness Visit 1-4 yrs new PT | B18: =[1]SourceValues!B18 -> 99382 | Z18: =SUM(W18:Y18) -> 0 | AA18: =[1]SourceValues!C18 -> 1.6 | AB18: =[1]SourceValues!D18 -> 3.28 | AC18: =[1]SourceValues!E18 -> 106.3048
... A55: =[1]SourceValues!A55 -> #REF! | B55: =[1]SourceValues!B55 -> #REF! | Z55: =SUM(W55:Y55) -> 0 | AA55: =[1]SourceValues!C55 -> #REF! | AB55: =[1]SourceValues!D55 -> #REF! | AC55: =[1]SourceValues!E55 -> 0
A56: =[1]SourceValues!A56 -> #REF! | B56: =[1]SourceValues!B56 -> #REF! | W56: =SUM(W7:W55) -> 0 | X56: =SUM(X7:X55) -> 0 | Y56: =SUM(Y7:Y55) -> 0 | Z56: =SUM(W56:Y56) -> 0 | AA56: =[1]SourceValues!C56 -> #REF! | AB56: =[1]SourceValues!D56 -> #REF! | AC56: =[1]SourceValues!E56 -> 0
A57: =[1]SourceValues!A57 -> Total Eye
A58: =[1]SourceValues!A58 -> Dental | B58: =[1]SourceValues!B58 -> #REF! | Z58: =SUM(W58:Y58) -> 0 | AA58: =[1]SourceValues!C58 -> #REF! | AB58: =[1]SourceValues!D58 -> #REF! | AC58: =[1]SourceValues!E58 -> #REF!
A59: =[1]SourceValues!A59 -> Limited oral evaluation | B59: =[1]SourceValues!B59 -> D0140 | Z59: =SUM(W59:Y59) -> 0 | AA59: =[1]SourceValues!C59 -> 0.75 | AB59: =[1]SourceValues!D59 -> 0.243075 | AC59: =[1]SourceValues!E59 -> 7.8780607
A60: =[1]SourceValues!A60 -> Comprehensive oral evaluation | B60: =[1]SourceValues!B60 -> D0150 | Z60: =SUM(W60:Y60) -> 0 | AA60: =[1]SourceValues!C60 -> 0.84 | AB60: =[1]SourceValues!D60 -> 0.272244 | AC60: =[1]SourceValues!E60 -> 8.823428
A61: =[1]SourceValues!A61 -> Detailed/extensive oral evaluation(oral cancer screening) | B61: =[1]SourceValues!B61 -> D0160 | Z61: =SUM(W61:Y61) -> 0 | AA61: =[1]SourceValues!C61 -> 1.38 | AB61: =[1]SourceValues!D61 -> 0.447258 | AC61: =[1]SourceValues!E61 -> 14.495632
A62: =[1]SourceValues!A62 -> Extraction, coronal rem - deciduous tooth | B62: =[1]SourceValues!B62 -> D7111 | Z62: =SUM(W62:Y62) -> 0 | AA62: =[1]SourceValues!C62 -> 1.17 | AB62: =[1]SourceValues!D62 -> 0.379197 | AC62: =[1]SourceValues!E62 -> 12.289775
A63: =[1]SourceValues!A63 -> Extraction, single tooth | B63: =[1]SourceValues!B63 -> D7140 | Z63: =SUM(W63:Y63) -> 0 | AA63: =[1]SourceValues!C63 -> 1.63 | AB63: =[1]SourceValues!D63 -> 0.528283 | AC63: =[1]SourceValues!E63 -> 17.121652
A64: =[1]SourceValues!A64 -> Surgical removal of erupted tooth | B64: =[1]SourceValues!B64 -> D7210 | Z64: =SUM(W64:Y64) -> 0 | AA64: =[1]SourceValues!C64 -> 2.76 | AB64: =[1]SourceValues!D64 -> 0.894516 | AC64: =[1]SourceValues!E64 -> 28.991264
A65: =[1]SourceValues!A65 -> Ext impacted tooth soft tissue | B65: =[1]SourceValues!B65 -> D7220 | Z65: =SUM(W65:Y65) -> 0 | AA65: =[1]SourceValues!C65 -> 3.26 | AB65: =[1]SourceValues!D65 -> 1.056566 | AC65: =[1]SourceValues!E65 -> 34.243304
A66: =[1]SourceValues!A66 -> Ext impacted tooth partial bony | B66: =[1]SourceValues!B66 -> D7230 | Z66: =SUM(W66:Y66) -> 0 | AA66: =[1]SourceValues!C66 -> 4.09 | AB66: =[1]SourceValues!D66 -> 1.325569 | AC66: =[1]SourceValues!E66 -> 42.961691
A67: =[1]SourceValues!A67 -> Ext impacted tooth comp bony | B67: =[1]SourceValues!B67 -> D7240 | Z67: =SUM(W67:Y67) -> 0 | AA67: =[1]SourceValues!C67 -> 4.84 | AB67: =[1]SourceValues!D67 -> 1.568644 | AC67: =[1]SourceValues!E67 -> 50.839752
A68: =[1]SourceValues!A68 -> Surgical removal of residual roots | B68: =[1]SourceValues!B68 -> D7250 | Z68: =SUM(W68:Y68) -> 0 | AA68: =[1]SourceValues!C68 -> 2.9 | AB68: =[1]SourceValues!D68 -> 0.93989 | AC68: =[1]SourceValues!E68 -> 30.461835
A69: =[1]SourceValues!A69 -> Alveoloplasty in conjunction with extractions-four or more teeth | B69: =[1]SourceValues!B69 -> D7310 | Z69: =SUM(W69:Y69) -> 0 | AA69: =[1]SourceValues!C69 -> 2.7 | AB69: =[1]SourceValues!D69 -> 0.87507 | AC69: =[1]SourceValues!E69 -> 28.361019
A70: =[1]SourceValues!A70 -> Alveoloplasty in conjunction with extractions-one to three teeth | B70: =[1]SourceValues!B70 -> D7311 | Z70: =SUM(W70:Y70) -> 0 | AA70: =[1]SourceValues!C70 -> 2.32 | AB70: =[1]SourceValues!D70 -> 0.751912 | AC70: =[1]SourceValues!E70 -> 24.369468
A71: =[1]SourceValues!A71 -> Cleaning of teeth | B71: =[1]SourceValues!B71 -> D1110 | W71: =SUM(W58:W70) -> 0 | X71: =SUM(X58:X70) -> 0 | Y71: =SUM(Y58:Y70) -> 0 | Z71: =SUM(W71:Y71) -> 0 | AA71: =[1]SourceValues!C71 -> 0.89 | AB71: =[1]SourceValues!D71 -> 0.288449 | AC71: =[1]SourceValues!E71 -> 9.3486321
A72: =[1]SourceValues!A72 -> Amalgam Filling-1 surface
A73: =[1]SourceValues!A73 -> Amalgam Filling-2 surface | B73: =[1]SourceValues!B73 -> D2150 | Z73: =SUM(W73:Y73) -> 0 | AA73: =[1]SourceValues!C73 -> 1.6 | AB73: =[1]SourceValues!D73 -> 0.51856 | AC73: =[1]SourceValues!E73 -> 16.80653
A74: =[1]SourceValues!A74 -> Amalgam Filling-3 surface | B74: =[1]SourceValues!B74 -> D2160 | Z74: =SUM(W74:Y74) -> 0 | AA74: =[1]SourceValues!C74 -> 1.95 | AB74: =[1]SourceValues!D74 -> 0.631995 | AC74: =[1]SourceValues!E74 -> 20.482958
